[2025-01-08T13:43:21.918-0800] {local_task_job_runner.py:123} INFO - ::group::Pre task execution logs
[2025-01-08T13:43:21.931-0800] {taskinstance.py:2613} INFO - Dependencies all met for dep_context=non-requeueable deps ti=<TaskInstance: CovidE2EPipeDag.insert_staged_raw_data manual__2025-01-08T21:36:10.704435+00:00 [queued]>
[2025-01-08T13:43:21.941-0800] {taskinstance.py:2613} INFO - Dependencies all met for dep_context=requeueable deps ti=<TaskInstance: CovidE2EPipeDag.insert_staged_raw_data manual__2025-01-08T21:36:10.704435+00:00 [queued]>
[2025-01-08T13:43:21.941-0800] {taskinstance.py:2866} INFO - Starting attempt 1 of 2
[2025-01-08T13:43:21.967-0800] {taskinstance.py:2889} INFO - Executing <Task(BashOperator): insert_staged_raw_data> on 2025-01-08 21:36:10.704435+00:00
[2025-01-08T13:43:21.973-0800] {standard_task_runner.py:72} INFO - Started process 6026 to run task
[2025-01-08T13:43:21.983-0800] {standard_task_runner.py:104} INFO - Running: ['airflow', 'tasks', 'run', 'CovidE2EPipeDag', 'insert_staged_raw_data', 'manual__2025-01-08T21:36:10.704435+00:00', '--job-id', '1212', '--raw', '--subdir', 'DAGS_FOLDER/CovidE2EPipeDag.py', '--cfg-path', '/var/folders/vm/rn9v1g1j739_mq8j5pfl1yxm0000gn/T/tmplyz8yh94']
[2025-01-08T13:43:21.985-0800] {standard_task_runner.py:105} INFO - Job 1212: Subtask insert_staged_raw_data
[2025-01-08T13:43:22.082-0800] {task_command.py:467} INFO - Running <TaskInstance: CovidE2EPipeDag.insert_staged_raw_data manual__2025-01-08T21:36:10.704435+00:00 [running]> on host Matthews-MacBook-Air.local
[2025-01-08T13:43:22.431-0800] {taskinstance.py:3132} INFO - Exporting env vars: AIRFLOW_CTX_DAG_OWNER='Matthew Horn' AIRFLOW_CTX_DAG_ID='CovidE2EPipeDag' AIRFLOW_CTX_TASK_ID='insert_staged_raw_data' AIRFLOW_CTX_EXECUTION_DATE='2025-01-08T21:36:10.704435+00:00' AIRFLOW_CTX_TRY_NUMBER='1' AIRFLOW_CTX_DAG_RUN_ID='manual__2025-01-08T21:36:10.704435+00:00'
[2025-01-08T13:43:22.432-0800] {taskinstance.py:731} INFO - ::endgroup::
[2025-01-08T13:43:22.516-0800] {subprocess.py:78} INFO - Tmp dir root location: /var/folders/vm/rn9v1g1j739_mq8j5pfl1yxm0000gn/T
[2025-01-08T13:43:22.517-0800] {subprocess.py:88} INFO - Running command: ['/bin/bash', '-c', 'snow stage execute @CovidE2EPipeDatabase.raw_data.raw_data_stage/load_staged_data_2025-01-08.sql']
[2025-01-08T13:43:22.530-0800] {subprocess.py:99} INFO - Output:
[2025-01-08T13:43:32.599-0800] {subprocess.py:106} INFO - 
[2025-01-08T13:43:32.601-0800] {subprocess.py:106} INFO - An unexpected exception occurred. Use --debug option to see the traceback. Exception message:
[2025-01-08T13:43:32.603-0800] {subprocess.py:106} INFO - 
[2025-01-08T13:43:32.604-0800] {subprocess.py:106} INFO - 001757 (42601): 01b99517-0004-7111-0003-5bfb0002e242: Uncaught exception of type 'STATEMENT_ERROR' in file @RAW_DATA_STAGE/load_staged_data_2025-01-08.sql on line 11 at position 4:
[2025-01-08T13:43:32.606-0800] {subprocess.py:106} INFO - SQL compilation error:
[2025-01-08T13:43:32.607-0800] {subprocess.py:106} INFO - Table 'COVIDE2EPIPEDATABASE.RAW_DATA.CURRENCY_EXCHANGE' does not exist
[2025-01-08T13:43:33.023-0800] {subprocess.py:110} INFO - Command exited with return code 1
[2025-01-08T13:43:33.035-0800] {taskinstance.py:3311} ERROR - Task failed with exception
Traceback (most recent call last):
  File "/opt/anaconda3/envs/airflow_env/lib/python3.9/site-packages/airflow/models/taskinstance.py", line 767, in _execute_task
    result = _execute_callable(context=context, **execute_callable_kwargs)
  File "/opt/anaconda3/envs/airflow_env/lib/python3.9/site-packages/airflow/models/taskinstance.py", line 733, in _execute_callable
    return ExecutionCallableRunner(
  File "/opt/anaconda3/envs/airflow_env/lib/python3.9/site-packages/airflow/utils/operator_helpers.py", line 252, in run
    return self.func(*args, **kwargs)
  File "/opt/anaconda3/envs/airflow_env/lib/python3.9/site-packages/airflow/models/baseoperator.py", line 422, in wrapper
    return func(self, *args, **kwargs)
  File "/opt/anaconda3/envs/airflow_env/lib/python3.9/site-packages/airflow/operators/bash.py", line 276, in execute
    raise AirflowException(
airflow.exceptions.AirflowException: Bash command failed. The command returned a non-zero exit code 1.
[2025-01-08T13:43:33.053-0800] {taskinstance.py:1225} INFO - Marking task as UP_FOR_RETRY. dag_id=CovidE2EPipeDag, task_id=insert_staged_raw_data, run_id=manual__2025-01-08T21:36:10.704435+00:00, execution_date=20250108T213610, start_date=20250108T214321, end_date=20250108T214333
[2025-01-08T13:43:33.076-0800] {taskinstance.py:340} INFO - ::group::Post task execution logs
[2025-01-08T13:43:33.077-0800] {standard_task_runner.py:124} ERROR - Failed to execute job 1212 for task insert_staged_raw_data (Bash command failed. The command returned a non-zero exit code 1.; 6026)
Traceback (most recent call last):
  File "/opt/anaconda3/envs/airflow_env/lib/python3.9/site-packages/airflow/task/task_runner/standard_task_runner.py", line 117, in _start_by_fork
    ret = args.func(args, dag=self.dag)
  File "/opt/anaconda3/envs/airflow_env/lib/python3.9/site-packages/airflow/cli/cli_config.py", line 49, in command
    return func(*args, **kwargs)
  File "/opt/anaconda3/envs/airflow_env/lib/python3.9/site-packages/airflow/utils/cli.py", line 116, in wrapper
    return f(*args, **kwargs)
  File "/opt/anaconda3/envs/airflow_env/lib/python3.9/site-packages/airflow/cli/commands/task_command.py", line 483, in task_run
    task_return_code = _run_task_by_selected_method(args, _dag, ti)
  File "/opt/anaconda3/envs/airflow_env/lib/python3.9/site-packages/airflow/cli/commands/task_command.py", line 256, in _run_task_by_selected_method
    return _run_raw_task(args, ti)
  File "/opt/anaconda3/envs/airflow_env/lib/python3.9/site-packages/airflow/cli/commands/task_command.py", line 341, in _run_raw_task
    return ti._run_raw_task(
  File "/opt/anaconda3/envs/airflow_env/lib/python3.9/site-packages/airflow/utils/session.py", line 97, in wrapper
    return func(*args, session=session, **kwargs)
  File "/opt/anaconda3/envs/airflow_env/lib/python3.9/site-packages/airflow/models/taskinstance.py", line 3005, in _run_raw_task
    return _run_raw_task(
  File "/opt/anaconda3/envs/airflow_env/lib/python3.9/site-packages/airflow/models/taskinstance.py", line 273, in _run_raw_task
    TaskInstance._execute_task_with_callbacks(
  File "/opt/anaconda3/envs/airflow_env/lib/python3.9/site-packages/airflow/models/taskinstance.py", line 3159, in _execute_task_with_callbacks
    result = self._execute_task(context, task_orig)
  File "/opt/anaconda3/envs/airflow_env/lib/python3.9/site-packages/airflow/models/taskinstance.py", line 3183, in _execute_task
    return _execute_task(self, context, task_orig)
  File "/opt/anaconda3/envs/airflow_env/lib/python3.9/site-packages/airflow/models/taskinstance.py", line 767, in _execute_task
    result = _execute_callable(context=context, **execute_callable_kwargs)
  File "/opt/anaconda3/envs/airflow_env/lib/python3.9/site-packages/airflow/models/taskinstance.py", line 733, in _execute_callable
    return ExecutionCallableRunner(
  File "/opt/anaconda3/envs/airflow_env/lib/python3.9/site-packages/airflow/utils/operator_helpers.py", line 252, in run
    return self.func(*args, **kwargs)
  File "/opt/anaconda3/envs/airflow_env/lib/python3.9/site-packages/airflow/models/baseoperator.py", line 422, in wrapper
    return func(self, *args, **kwargs)
  File "/opt/anaconda3/envs/airflow_env/lib/python3.9/site-packages/airflow/operators/bash.py", line 276, in execute
    raise AirflowException(
airflow.exceptions.AirflowException: Bash command failed. The command returned a non-zero exit code 1.
[2025-01-08T13:43:33.099-0800] {local_task_job_runner.py:266} INFO - Task exited with return code 1
[2025-01-08T13:43:33.145-0800] {taskinstance.py:3895} INFO - 0 downstream tasks scheduled from follow-on schedule check
[2025-01-08T13:43:33.147-0800] {local_task_job_runner.py:245} INFO - ::endgroup::
