[2025-01-09T16:59:55.317-0800] {local_task_job_runner.py:123} INFO - ::group::Pre task execution logs
[2025-01-09T16:59:55.342-0800] {taskinstance.py:2613} INFO - Dependencies all met for dep_context=non-requeueable deps ti=<TaskInstance: CovidE2EPipeDag.archive_raw_data scheduled__2025-01-08T20:00:00+00:00 [queued]>
[2025-01-09T16:59:55.358-0800] {taskinstance.py:2613} INFO - Dependencies all met for dep_context=requeueable deps ti=<TaskInstance: CovidE2EPipeDag.archive_raw_data scheduled__2025-01-08T20:00:00+00:00 [queued]>
[2025-01-09T16:59:55.359-0800] {taskinstance.py:2866} INFO - Starting attempt 2 of 2
[2025-01-09T16:59:55.387-0800] {taskinstance.py:2889} INFO - Executing <Task(BashOperator): archive_raw_data> on 2025-01-08 20:00:00+00:00
[2025-01-09T16:59:55.392-0800] {standard_task_runner.py:72} INFO - Started process 16920 to run task
[2025-01-09T16:59:55.403-0800] {standard_task_runner.py:104} INFO - Running: ['airflow', 'tasks', 'run', 'CovidE2EPipeDag', 'archive_raw_data', 'scheduled__2025-01-08T20:00:00+00:00', '--job-id', '1756', '--raw', '--subdir', 'DAGS_FOLDER/CovidE2EPipeDag.py', '--cfg-path', '/var/folders/vm/rn9v1g1j739_mq8j5pfl1yxm0000gn/T/tmp_k1d_a7z']
[2025-01-09T16:59:55.407-0800] {standard_task_runner.py:105} INFO - Job 1756: Subtask archive_raw_data
[2025-01-09T16:59:55.489-0800] {task_command.py:467} INFO - Running <TaskInstance: CovidE2EPipeDag.archive_raw_data scheduled__2025-01-08T20:00:00+00:00 [running]> on host Matthews-MacBook-Air.local
[2025-01-09T16:59:55.710-0800] {taskinstance.py:3132} INFO - Exporting env vars: AIRFLOW_CTX_DAG_OWNER='Matthew Horn' AIRFLOW_CTX_DAG_ID='CovidE2EPipeDag' AIRFLOW_CTX_TASK_ID='archive_raw_data' AIRFLOW_CTX_EXECUTION_DATE='2025-01-08T20:00:00+00:00' AIRFLOW_CTX_TRY_NUMBER='2' AIRFLOW_CTX_DAG_RUN_ID='scheduled__2025-01-08T20:00:00+00:00'
[2025-01-09T16:59:55.712-0800] {taskinstance.py:731} INFO - ::endgroup::
[2025-01-09T16:59:55.768-0800] {subprocess.py:78} INFO - Tmp dir root location: /var/folders/vm/rn9v1g1j739_mq8j5pfl1yxm0000gn/T
[2025-01-09T16:59:55.770-0800] {subprocess.py:88} INFO - Running command: ['/bin/bash', '-c', 'cd /Users/matthewmac/airflow/data/raw && zip raw_data_2025-01-09.zip *.csv;                    mv raw_data_2025-01-09.zip archived; rm "/Users/matthewmac/airflow/data/raw/*.csv"']
[2025-01-09T16:59:55.780-0800] {subprocess.py:99} INFO - Output:
[2025-01-09T16:59:55.804-0800] {subprocess.py:106} INFO -   adding: 30yr_mortage_2025-01-09.csv (deflated 82%)
[2025-01-09T16:59:55.805-0800] {subprocess.py:106} INFO -   adding: GDP_2025-01-09.csv (deflated 77%)
[2025-01-09T16:59:55.806-0800] {subprocess.py:106} INFO -   adding: US_CPI_2025-01-09.csv (deflated 81%)
[2025-01-09T16:59:55.809-0800] {subprocess.py:106} INFO -   adding: industrial_production_2025-01-09.csv (deflated 80%)
[2025-01-09T16:59:55.810-0800] {subprocess.py:106} INFO -   adding: trade_balance_2025-01-09.csv (deflated 79%)
[2025-01-09T16:59:55.811-0800] {subprocess.py:106} INFO -   adding: unemployment_rate_2025-01-09.csv (deflated 84%)
[2025-01-09T16:59:55.831-0800] {subprocess.py:106} INFO - rm: /Users/matthewmac/airflow/data/raw/*.csv: No such file or directory
[2025-01-09T16:59:55.832-0800] {subprocess.py:110} INFO - Command exited with return code 1
[2025-01-09T16:59:55.844-0800] {taskinstance.py:3311} ERROR - Task failed with exception
Traceback (most recent call last):
  File "/opt/anaconda3/envs/airflow_env/lib/python3.9/site-packages/airflow/models/taskinstance.py", line 767, in _execute_task
    result = _execute_callable(context=context, **execute_callable_kwargs)
  File "/opt/anaconda3/envs/airflow_env/lib/python3.9/site-packages/airflow/models/taskinstance.py", line 733, in _execute_callable
    return ExecutionCallableRunner(
  File "/opt/anaconda3/envs/airflow_env/lib/python3.9/site-packages/airflow/utils/operator_helpers.py", line 252, in run
    return self.func(*args, **kwargs)
  File "/opt/anaconda3/envs/airflow_env/lib/python3.9/site-packages/airflow/models/baseoperator.py", line 422, in wrapper
    return func(self, *args, **kwargs)
  File "/opt/anaconda3/envs/airflow_env/lib/python3.9/site-packages/airflow/operators/bash.py", line 276, in execute
    raise AirflowException(
airflow.exceptions.AirflowException: Bash command failed. The command returned a non-zero exit code 1.
[2025-01-09T16:59:55.856-0800] {taskinstance.py:1225} INFO - Marking task as FAILED. dag_id=CovidE2EPipeDag, task_id=archive_raw_data, run_id=scheduled__2025-01-08T20:00:00+00:00, execution_date=20250108T200000, start_date=20250110T005955, end_date=20250110T005955
[2025-01-09T16:59:55.873-0800] {taskinstance.py:340} INFO - ::group::Post task execution logs
[2025-01-09T16:59:55.874-0800] {standard_task_runner.py:124} ERROR - Failed to execute job 1756 for task archive_raw_data (Bash command failed. The command returned a non-zero exit code 1.; 16920)
Traceback (most recent call last):
  File "/opt/anaconda3/envs/airflow_env/lib/python3.9/site-packages/airflow/task/task_runner/standard_task_runner.py", line 117, in _start_by_fork
    ret = args.func(args, dag=self.dag)
  File "/opt/anaconda3/envs/airflow_env/lib/python3.9/site-packages/airflow/cli/cli_config.py", line 49, in command
    return func(*args, **kwargs)
  File "/opt/anaconda3/envs/airflow_env/lib/python3.9/site-packages/airflow/utils/cli.py", line 116, in wrapper
    return f(*args, **kwargs)
  File "/opt/anaconda3/envs/airflow_env/lib/python3.9/site-packages/airflow/cli/commands/task_command.py", line 483, in task_run
    task_return_code = _run_task_by_selected_method(args, _dag, ti)
  File "/opt/anaconda3/envs/airflow_env/lib/python3.9/site-packages/airflow/cli/commands/task_command.py", line 256, in _run_task_by_selected_method
    return _run_raw_task(args, ti)
  File "/opt/anaconda3/envs/airflow_env/lib/python3.9/site-packages/airflow/cli/commands/task_command.py", line 341, in _run_raw_task
    return ti._run_raw_task(
  File "/opt/anaconda3/envs/airflow_env/lib/python3.9/site-packages/airflow/utils/session.py", line 97, in wrapper
    return func(*args, session=session, **kwargs)
  File "/opt/anaconda3/envs/airflow_env/lib/python3.9/site-packages/airflow/models/taskinstance.py", line 3005, in _run_raw_task
    return _run_raw_task(
  File "/opt/anaconda3/envs/airflow_env/lib/python3.9/site-packages/airflow/models/taskinstance.py", line 273, in _run_raw_task
    TaskInstance._execute_task_with_callbacks(
  File "/opt/anaconda3/envs/airflow_env/lib/python3.9/site-packages/airflow/models/taskinstance.py", line 3159, in _execute_task_with_callbacks
    result = self._execute_task(context, task_orig)
  File "/opt/anaconda3/envs/airflow_env/lib/python3.9/site-packages/airflow/models/taskinstance.py", line 3183, in _execute_task
    return _execute_task(self, context, task_orig)
  File "/opt/anaconda3/envs/airflow_env/lib/python3.9/site-packages/airflow/models/taskinstance.py", line 767, in _execute_task
    result = _execute_callable(context=context, **execute_callable_kwargs)
  File "/opt/anaconda3/envs/airflow_env/lib/python3.9/site-packages/airflow/models/taskinstance.py", line 733, in _execute_callable
    return ExecutionCallableRunner(
  File "/opt/anaconda3/envs/airflow_env/lib/python3.9/site-packages/airflow/utils/operator_helpers.py", line 252, in run
    return self.func(*args, **kwargs)
  File "/opt/anaconda3/envs/airflow_env/lib/python3.9/site-packages/airflow/models/baseoperator.py", line 422, in wrapper
    return func(self, *args, **kwargs)
  File "/opt/anaconda3/envs/airflow_env/lib/python3.9/site-packages/airflow/operators/bash.py", line 276, in execute
    raise AirflowException(
airflow.exceptions.AirflowException: Bash command failed. The command returned a non-zero exit code 1.
[2025-01-09T16:59:55.917-0800] {local_task_job_runner.py:266} INFO - Task exited with return code 1
[2025-01-09T16:59:55.957-0800] {taskinstance.py:3895} INFO - 0 downstream tasks scheduled from follow-on schedule check
[2025-01-09T16:59:55.969-0800] {local_task_job_runner.py:245} INFO - ::endgroup::
