[2025-01-08T16:48:12.930-0800] {local_task_job_runner.py:123} INFO - ::group::Pre task execution logs
[2025-01-08T16:48:12.942-0800] {taskinstance.py:2613} INFO - Dependencies all met for dep_context=non-requeueable deps ti=<TaskInstance: CovidE2EPipeDag.stage_raw_data manual__2025-01-09T00:45:01.875486+00:00 [queued]>
[2025-01-08T16:48:12.951-0800] {taskinstance.py:2613} INFO - Dependencies all met for dep_context=requeueable deps ti=<TaskInstance: CovidE2EPipeDag.stage_raw_data manual__2025-01-09T00:45:01.875486+00:00 [queued]>
[2025-01-08T16:48:12.951-0800] {taskinstance.py:2866} INFO - Starting attempt 1 of 2
[2025-01-08T16:48:12.968-0800] {taskinstance.py:2889} INFO - Executing <Task(BashOperator): stage_raw_data> on 2025-01-09 00:45:01.875486+00:00
[2025-01-08T16:48:12.971-0800] {standard_task_runner.py:72} INFO - Started process 17468 to run task
[2025-01-08T16:48:12.981-0800] {standard_task_runner.py:104} INFO - Running: ['airflow', 'tasks', 'run', 'CovidE2EPipeDag', 'stage_raw_data', 'manual__2025-01-09T00:45:01.875486+00:00', '--job-id', '1526', '--raw', '--subdir', 'DAGS_FOLDER/CovidE2EPipeDag.py', '--cfg-path', '/var/folders/vm/rn9v1g1j739_mq8j5pfl1yxm0000gn/T/tmppfsbu3n2']
[2025-01-08T16:48:12.984-0800] {standard_task_runner.py:105} INFO - Job 1526: Subtask stage_raw_data
[2025-01-08T16:48:13.037-0800] {task_command.py:467} INFO - Running <TaskInstance: CovidE2EPipeDag.stage_raw_data manual__2025-01-09T00:45:01.875486+00:00 [running]> on host Matthews-MacBook-Air.local
[2025-01-08T16:48:13.127-0800] {taskinstance.py:3132} INFO - Exporting env vars: AIRFLOW_CTX_DAG_OWNER='Matthew Horn' AIRFLOW_CTX_DAG_ID='CovidE2EPipeDag' AIRFLOW_CTX_TASK_ID='stage_raw_data' AIRFLOW_CTX_EXECUTION_DATE='2025-01-09T00:45:01.875486+00:00' AIRFLOW_CTX_TRY_NUMBER='1' AIRFLOW_CTX_DAG_RUN_ID='manual__2025-01-09T00:45:01.875486+00:00'
[2025-01-08T16:48:13.129-0800] {taskinstance.py:731} INFO - ::endgroup::
[2025-01-08T16:48:13.149-0800] {subprocess.py:78} INFO - Tmp dir root location: /var/folders/vm/rn9v1g1j739_mq8j5pfl1yxm0000gn/T
[2025-01-08T16:48:13.150-0800] {subprocess.py:88} INFO - Running command: ['/bin/bash', '-c', 'snow stage copy /Users/matthewmac/airflow/data/raw/industrial_production_2025-01-09.csv @CovidE2EPipeDatabase.raw_data.raw_data_stage']
[2025-01-08T16:48:13.157-0800] {subprocess.py:99} INFO - Output:
[2025-01-08T16:48:18.819-0800] {subprocess.py:106} INFO - 
[2025-01-08T16:48:18.821-0800] {subprocess.py:106} INFO - An unexpected exception occurred. Use --debug option to see the traceback. Exception message:
[2025-01-08T16:48:18.822-0800] {subprocess.py:106} INFO - 
[2025-01-08T16:48:18.823-0800] {subprocess.py:106} INFO - 253006: 253006: File doesn't exist: ['/Users/matthewmac/airflow/data/raw/industrial_production_2025-01-09.csv']
[2025-01-08T16:48:19.196-0800] {subprocess.py:110} INFO - Command exited with return code 1
[2025-01-08T16:48:19.211-0800] {taskinstance.py:3311} ERROR - Task failed with exception
Traceback (most recent call last):
  File "/opt/anaconda3/envs/airflow_env/lib/python3.9/site-packages/airflow/models/taskinstance.py", line 767, in _execute_task
    result = _execute_callable(context=context, **execute_callable_kwargs)
  File "/opt/anaconda3/envs/airflow_env/lib/python3.9/site-packages/airflow/models/taskinstance.py", line 733, in _execute_callable
    return ExecutionCallableRunner(
  File "/opt/anaconda3/envs/airflow_env/lib/python3.9/site-packages/airflow/utils/operator_helpers.py", line 252, in run
    return self.func(*args, **kwargs)
  File "/opt/anaconda3/envs/airflow_env/lib/python3.9/site-packages/airflow/models/baseoperator.py", line 422, in wrapper
    return func(self, *args, **kwargs)
  File "/opt/anaconda3/envs/airflow_env/lib/python3.9/site-packages/airflow/operators/bash.py", line 276, in execute
    raise AirflowException(
airflow.exceptions.AirflowException: Bash command failed. The command returned a non-zero exit code 1.
[2025-01-08T16:48:19.227-0800] {taskinstance.py:1225} INFO - Marking task as UP_FOR_RETRY. dag_id=CovidE2EPipeDag, task_id=stage_raw_data, run_id=manual__2025-01-09T00:45:01.875486+00:00, execution_date=20250109T004501, start_date=20250109T004812, end_date=20250109T004819
[2025-01-08T16:48:19.250-0800] {taskinstance.py:340} INFO - ::group::Post task execution logs
[2025-01-08T16:48:19.251-0800] {standard_task_runner.py:124} ERROR - Failed to execute job 1526 for task stage_raw_data (Bash command failed. The command returned a non-zero exit code 1.; 17468)
Traceback (most recent call last):
  File "/opt/anaconda3/envs/airflow_env/lib/python3.9/site-packages/airflow/task/task_runner/standard_task_runner.py", line 117, in _start_by_fork
    ret = args.func(args, dag=self.dag)
  File "/opt/anaconda3/envs/airflow_env/lib/python3.9/site-packages/airflow/cli/cli_config.py", line 49, in command
    return func(*args, **kwargs)
  File "/opt/anaconda3/envs/airflow_env/lib/python3.9/site-packages/airflow/utils/cli.py", line 116, in wrapper
    return f(*args, **kwargs)
  File "/opt/anaconda3/envs/airflow_env/lib/python3.9/site-packages/airflow/cli/commands/task_command.py", line 483, in task_run
    task_return_code = _run_task_by_selected_method(args, _dag, ti)
  File "/opt/anaconda3/envs/airflow_env/lib/python3.9/site-packages/airflow/cli/commands/task_command.py", line 256, in _run_task_by_selected_method
    return _run_raw_task(args, ti)
  File "/opt/anaconda3/envs/airflow_env/lib/python3.9/site-packages/airflow/cli/commands/task_command.py", line 341, in _run_raw_task
    return ti._run_raw_task(
  File "/opt/anaconda3/envs/airflow_env/lib/python3.9/site-packages/airflow/utils/session.py", line 97, in wrapper
    return func(*args, session=session, **kwargs)
  File "/opt/anaconda3/envs/airflow_env/lib/python3.9/site-packages/airflow/models/taskinstance.py", line 3005, in _run_raw_task
    return _run_raw_task(
  File "/opt/anaconda3/envs/airflow_env/lib/python3.9/site-packages/airflow/models/taskinstance.py", line 273, in _run_raw_task
    TaskInstance._execute_task_with_callbacks(
  File "/opt/anaconda3/envs/airflow_env/lib/python3.9/site-packages/airflow/models/taskinstance.py", line 3159, in _execute_task_with_callbacks
    result = self._execute_task(context, task_orig)
  File "/opt/anaconda3/envs/airflow_env/lib/python3.9/site-packages/airflow/models/taskinstance.py", line 3183, in _execute_task
    return _execute_task(self, context, task_orig)
  File "/opt/anaconda3/envs/airflow_env/lib/python3.9/site-packages/airflow/models/taskinstance.py", line 767, in _execute_task
    result = _execute_callable(context=context, **execute_callable_kwargs)
  File "/opt/anaconda3/envs/airflow_env/lib/python3.9/site-packages/airflow/models/taskinstance.py", line 733, in _execute_callable
    return ExecutionCallableRunner(
  File "/opt/anaconda3/envs/airflow_env/lib/python3.9/site-packages/airflow/utils/operator_helpers.py", line 252, in run
    return self.func(*args, **kwargs)
  File "/opt/anaconda3/envs/airflow_env/lib/python3.9/site-packages/airflow/models/baseoperator.py", line 422, in wrapper
    return func(self, *args, **kwargs)
  File "/opt/anaconda3/envs/airflow_env/lib/python3.9/site-packages/airflow/operators/bash.py", line 276, in execute
    raise AirflowException(
airflow.exceptions.AirflowException: Bash command failed. The command returned a non-zero exit code 1.
[2025-01-08T16:48:19.301-0800] {local_task_job_runner.py:266} INFO - Task exited with return code 1
[2025-01-08T16:48:19.333-0800] {taskinstance.py:3895} INFO - 0 downstream tasks scheduled from follow-on schedule check
[2025-01-08T16:48:19.334-0800] {local_task_job_runner.py:245} INFO - ::endgroup::
