[2025-01-03T11:55:58.478-0800] {processor.py:186} INFO - Started process (PID=51620) to work on /Users/matthewmac/airflow/dags/CovidPipeDag.py
[2025-01-03T11:55:58.480-0800] {processor.py:914} INFO - Processing file /Users/matthewmac/airflow/dags/CovidPipeDag.py for tasks to queue
[2025-01-03T11:55:58.482-0800] {logging_mixin.py:190} INFO - [2025-01-03T11:55:58.481-0800] {dagbag.py:588} INFO - Filling up the DagBag from /Users/matthewmac/airflow/dags/CovidPipeDag.py
[2025-01-03T11:56:00.447-0800] {logging_mixin.py:190} INFO - [2025-01-03T11:56:00.433-0800] {dagbag.py:387} ERROR - Failed to import: /Users/matthewmac/airflow/dags/CovidPipeDag.py
Traceback (most recent call last):
  File "/opt/anaconda3/envs/airflow_env/lib/python3.9/site-packages/airflow/models/dagbag.py", line 383, in parse
    loader.exec_module(new_module)
  File "<frozen importlib._bootstrap_external>", line 850, in exec_module
  File "<frozen importlib._bootstrap>", line 228, in _call_with_frames_removed
  File "/Users/matthewmac/airflow/dags/CovidPipeDag.py", line 4, in <module>
    from airflow.providers.snowflake.operators.snowflake import SnowflakeOperator
ImportError: cannot import name 'SnowflakeOperator' from 'airflow.providers.snowflake.operators.snowflake' (/opt/anaconda3/envs/airflow_env/lib/python3.9/site-packages/airflow/providers/snowflake/operators/snowflake.py)
[2025-01-03T11:56:00.448-0800] {processor.py:927} WARNING - No viable dags retrieved from /Users/matthewmac/airflow/dags/CovidPipeDag.py
[2025-01-03T11:56:00.753-0800] {processor.py:208} INFO - Processing /Users/matthewmac/airflow/dags/CovidPipeDag.py took 2.284 seconds
[2025-01-03T12:00:58.773-0800] {processor.py:186} INFO - Started process (PID=52118) to work on /Users/matthewmac/airflow/dags/CovidPipeDag.py
[2025-01-03T12:00:58.776-0800] {processor.py:914} INFO - Processing file /Users/matthewmac/airflow/dags/CovidPipeDag.py for tasks to queue
[2025-01-03T12:00:58.777-0800] {logging_mixin.py:190} INFO - [2025-01-03T12:00:58.777-0800] {dagbag.py:588} INFO - Filling up the DagBag from /Users/matthewmac/airflow/dags/CovidPipeDag.py
[2025-01-03T12:01:01.601-0800] {logging_mixin.py:190} INFO - [2025-01-03T12:01:01.597-0800] {dagbag.py:387} ERROR - Failed to import: /Users/matthewmac/airflow/dags/CovidPipeDag.py
Traceback (most recent call last):
  File "/opt/anaconda3/envs/airflow_env/lib/python3.9/site-packages/airflow/models/dagbag.py", line 383, in parse
    loader.exec_module(new_module)
  File "<frozen importlib._bootstrap_external>", line 850, in exec_module
  File "<frozen importlib._bootstrap>", line 228, in _call_with_frames_removed
  File "/Users/matthewmac/airflow/dags/CovidPipeDag.py", line 4, in <module>
    from airflow.providers.snowflake.operators.snowflake import SnowflakeOperator
ImportError: cannot import name 'SnowflakeOperator' from 'airflow.providers.snowflake.operators.snowflake' (/opt/anaconda3/envs/airflow_env/lib/python3.9/site-packages/airflow/providers/snowflake/operators/snowflake.py)
[2025-01-03T12:01:01.602-0800] {processor.py:927} WARNING - No viable dags retrieved from /Users/matthewmac/airflow/dags/CovidPipeDag.py
[2025-01-03T12:01:01.776-0800] {processor.py:208} INFO - Processing /Users/matthewmac/airflow/dags/CovidPipeDag.py took 3.019 seconds
[2025-01-03T12:06:35.851-0800] {processor.py:186} INFO - Started process (PID=52371) to work on /Users/matthewmac/airflow/dags/CovidPipeDag.py
[2025-01-03T12:06:35.854-0800] {processor.py:914} INFO - Processing file /Users/matthewmac/airflow/dags/CovidPipeDag.py for tasks to queue
[2025-01-03T12:06:35.859-0800] {logging_mixin.py:190} INFO - [2025-01-03T12:06:35.857-0800] {dagbag.py:588} INFO - Filling up the DagBag from /Users/matthewmac/airflow/dags/CovidPipeDag.py
[2025-01-03T12:06:39.437-0800] {logging_mixin.py:190} INFO - [2025-01-03T12:06:39.433-0800] {dagbag.py:387} ERROR - Failed to import: /Users/matthewmac/airflow/dags/CovidPipeDag.py
Traceback (most recent call last):
  File "/opt/anaconda3/envs/airflow_env/lib/python3.9/site-packages/airflow/models/dagbag.py", line 383, in parse
    loader.exec_module(new_module)
  File "<frozen importlib._bootstrap_external>", line 850, in exec_module
  File "<frozen importlib._bootstrap>", line 228, in _call_with_frames_removed
  File "/Users/matthewmac/airflow/dags/CovidPipeDag.py", line 4, in <module>
    from airflow.providers.snowflake.operators.snowflake import SnowflakeOperator
ImportError: cannot import name 'SnowflakeOperator' from 'airflow.providers.snowflake.operators.snowflake' (/opt/anaconda3/envs/airflow_env/lib/python3.9/site-packages/airflow/providers/snowflake/operators/snowflake.py)
[2025-01-03T12:06:39.438-0800] {processor.py:927} WARNING - No viable dags retrieved from /Users/matthewmac/airflow/dags/CovidPipeDag.py
[2025-01-03T12:06:39.715-0800] {processor.py:208} INFO - Processing /Users/matthewmac/airflow/dags/CovidPipeDag.py took 3.875 seconds
[2025-01-03T12:11:48.188-0800] {processor.py:186} INFO - Started process (PID=52811) to work on /Users/matthewmac/airflow/dags/CovidPipeDag.py
[2025-01-03T12:11:48.193-0800] {processor.py:914} INFO - Processing file /Users/matthewmac/airflow/dags/CovidPipeDag.py for tasks to queue
[2025-01-03T12:11:48.194-0800] {logging_mixin.py:190} INFO - [2025-01-03T12:11:48.194-0800] {dagbag.py:588} INFO - Filling up the DagBag from /Users/matthewmac/airflow/dags/CovidPipeDag.py
[2025-01-03T12:11:52.435-0800] {logging_mixin.py:190} INFO - [2025-01-03T12:11:52.432-0800] {dagbag.py:387} ERROR - Failed to import: /Users/matthewmac/airflow/dags/CovidPipeDag.py
Traceback (most recent call last):
  File "/opt/anaconda3/envs/airflow_env/lib/python3.9/site-packages/airflow/models/dagbag.py", line 383, in parse
    loader.exec_module(new_module)
  File "<frozen importlib._bootstrap_external>", line 850, in exec_module
  File "<frozen importlib._bootstrap>", line 228, in _call_with_frames_removed
  File "/Users/matthewmac/airflow/dags/CovidPipeDag.py", line 4, in <module>
    from airflow.providers.snowflake.operators.snowflake import SnowflakeOperator
ImportError: cannot import name 'SnowflakeOperator' from 'airflow.providers.snowflake.operators.snowflake' (/opt/anaconda3/envs/airflow_env/lib/python3.9/site-packages/airflow/providers/snowflake/operators/snowflake.py)
[2025-01-03T12:11:52.608-0800] {logging_mixin.py:190} WARNING - /opt/anaconda3/envs/airflow_env/lib/python3.9/site-packages/snowflake/connector/options.py:94 UserWarning: You have an incompatible version of 'pyarrow' installed (18.1.0), please install a version that adheres to: 'pyarrow<3.1.0,>=3.0.0; extra == "pandas"'
[2025-01-03T12:11:52.610-0800] {processor.py:927} WARNING - No viable dags retrieved from /Users/matthewmac/airflow/dags/CovidPipeDag.py
[2025-01-03T12:11:52.957-0800] {processor.py:208} INFO - Processing /Users/matthewmac/airflow/dags/CovidPipeDag.py took 4.774 seconds
