[2025-01-04T10:38:50.458-0800] {local_task_job_runner.py:123} INFO - ::group::Pre task execution logs
[2025-01-04T10:38:50.507-0800] {taskinstance.py:2613} INFO - Dependencies all met for dep_context=non-requeueable deps ti=<TaskInstance: CovidE2EPipeDag.stage_raw_data scheduled__2025-01-01T00:52:00+00:00 [queued]>
[2025-01-04T10:38:50.515-0800] {taskinstance.py:2613} INFO - Dependencies all met for dep_context=requeueable deps ti=<TaskInstance: CovidE2EPipeDag.stage_raw_data scheduled__2025-01-01T00:52:00+00:00 [queued]>
[2025-01-04T10:38:50.516-0800] {taskinstance.py:2866} INFO - Starting attempt 2 of 2
[2025-01-04T10:38:50.533-0800] {taskinstance.py:2889} INFO - Executing <Task(BashOperator): stage_raw_data> on 2025-01-01 00:52:00+00:00
[2025-01-04T10:38:50.536-0800] {standard_task_runner.py:72} INFO - Started process 74782 to run task
[2025-01-04T10:38:50.545-0800] {standard_task_runner.py:104} INFO - Running: ['airflow', 'tasks', 'run', 'CovidE2EPipeDag', 'stage_raw_data', 'scheduled__2025-01-01T00:52:00+00:00', '--job-id', '800', '--raw', '--subdir', 'DAGS_FOLDER/CovidE2EPipeDag.py', '--cfg-path', '/var/folders/vm/rn9v1g1j739_mq8j5pfl1yxm0000gn/T/tmp2_27rmyn']
[2025-01-04T10:38:50.548-0800] {standard_task_runner.py:105} INFO - Job 800: Subtask stage_raw_data
[2025-01-04T10:38:50.610-0800] {task_command.py:467} INFO - Running <TaskInstance: CovidE2EPipeDag.stage_raw_data scheduled__2025-01-01T00:52:00+00:00 [running]> on host Matthews-MacBook-Air.local
[2025-01-04T10:38:50.688-0800] {taskinstance.py:3132} INFO - Exporting env vars: AIRFLOW_CTX_DAG_OWNER='Matthew Horn' AIRFLOW_CTX_DAG_ID='CovidE2EPipeDag' AIRFLOW_CTX_TASK_ID='stage_raw_data' AIRFLOW_CTX_EXECUTION_DATE='2025-01-01T00:52:00+00:00' AIRFLOW_CTX_TRY_NUMBER='2' AIRFLOW_CTX_DAG_RUN_ID='scheduled__2025-01-01T00:52:00+00:00'
[2025-01-04T10:38:50.691-0800] {logging_mixin.py:190} INFO - Task instance is in running state
[2025-01-04T10:38:50.692-0800] {logging_mixin.py:190} INFO -  Previous state of the Task instance: queued
[2025-01-04T10:38:50.694-0800] {logging_mixin.py:190} INFO - Current task name:stage_raw_data state:running start_date:2025-01-04 18:38:50.507559+00:00
[2025-01-04T10:38:50.694-0800] {logging_mixin.py:190} INFO - Dag name:CovidE2EPipeDag and current dag run status:running
[2025-01-04T10:38:50.695-0800] {taskinstance.py:731} INFO - ::endgroup::
[2025-01-04T10:38:50.696-0800] {subprocess.py:78} INFO - Tmp dir root location: /var/folders/vm/rn9v1g1j739_mq8j5pfl1yxm0000gn/T
[2025-01-04T10:38:50.697-0800] {subprocess.py:88} INFO - Running command: ['/bin/bash', '-c', 'snow stage copy ~/airflow/data/raw/industrial_production_2025-01-04.csv @CovidE2EPipeline.raw_data.raw_data_stage']
[2025-01-04T10:38:50.708-0800] {subprocess.py:99} INFO - Output:
[2025-01-04T10:38:55.569-0800] {subprocess.py:106} INFO - 
[2025-01-04T10:38:55.570-0800] {subprocess.py:106} INFO - An unexpected exception occurred. Use --debug option to see the traceback. Exception message:
[2025-01-04T10:38:55.572-0800] {subprocess.py:106} INFO - 
[2025-01-04T10:38:55.572-0800] {subprocess.py:106} INFO - 002003 (02000): 01b97dde-0004-6978-0003-5bfb00020122: SQL compilation error:
[2025-01-04T10:38:55.575-0800] {subprocess.py:106} INFO - Database 'COVIDE2EPIPELINE' does not exist or not authorized.
[2025-01-04T10:38:55.945-0800] {subprocess.py:110} INFO - Command exited with return code 1
[2025-01-04T10:38:55.960-0800] {taskinstance.py:3311} ERROR - Task failed with exception
Traceback (most recent call last):
  File "/opt/anaconda3/envs/airflow_env/lib/python3.9/site-packages/airflow/models/taskinstance.py", line 767, in _execute_task
    result = _execute_callable(context=context, **execute_callable_kwargs)
  File "/opt/anaconda3/envs/airflow_env/lib/python3.9/site-packages/airflow/models/taskinstance.py", line 733, in _execute_callable
    return ExecutionCallableRunner(
  File "/opt/anaconda3/envs/airflow_env/lib/python3.9/site-packages/airflow/utils/operator_helpers.py", line 252, in run
    return self.func(*args, **kwargs)
  File "/opt/anaconda3/envs/airflow_env/lib/python3.9/site-packages/airflow/models/baseoperator.py", line 422, in wrapper
    return func(self, *args, **kwargs)
  File "/opt/anaconda3/envs/airflow_env/lib/python3.9/site-packages/airflow/operators/bash.py", line 276, in execute
    raise AirflowException(
airflow.exceptions.AirflowException: Bash command failed. The command returned a non-zero exit code 1.
[2025-01-04T10:38:55.968-0800] {logging_mixin.py:190} INFO - Task instance in failure state
[2025-01-04T10:38:55.970-0800] {logging_mixin.py:190} INFO - Task start:2025-01-04 18:38:50.507559+00:00 end:2025-01-04 18:38:55.967240+00:00 duration:5.459681
[2025-01-04T10:38:55.971-0800] {logging_mixin.py:190} INFO - Task:<Task(BashOperator): stage_raw_data> dag:<DAG: CovidE2EPipeDag> dagrun:<DagRun CovidE2EPipeDag @ 2025-01-01 00:52:00+00:00: scheduled__2025-01-01T00:52:00+00:00, state:running, queued_at: 2025-01-04 18:30:03.652293+00:00. externally triggered: False>
[2025-01-04T10:38:55.972-0800] {logging_mixin.py:190} INFO - Failure caused by Bash command failed. The command returned a non-zero exit code 1.
[2025-01-04T10:38:55.975-0800] {taskinstance.py:1225} INFO - Marking task as FAILED. dag_id=CovidE2EPipeDag, task_id=stage_raw_data, run_id=scheduled__2025-01-01T00:52:00+00:00, execution_date=20250101T005200, start_date=20250104T183850, end_date=20250104T183855
[2025-01-04T10:38:55.988-0800] {taskinstance.py:340} INFO - ::group::Post task execution logs
[2025-01-04T10:38:55.989-0800] {standard_task_runner.py:124} ERROR - Failed to execute job 800 for task stage_raw_data (Bash command failed. The command returned a non-zero exit code 1.; 74782)
Traceback (most recent call last):
  File "/opt/anaconda3/envs/airflow_env/lib/python3.9/site-packages/airflow/task/task_runner/standard_task_runner.py", line 117, in _start_by_fork
    ret = args.func(args, dag=self.dag)
  File "/opt/anaconda3/envs/airflow_env/lib/python3.9/site-packages/airflow/cli/cli_config.py", line 49, in command
    return func(*args, **kwargs)
  File "/opt/anaconda3/envs/airflow_env/lib/python3.9/site-packages/airflow/utils/cli.py", line 116, in wrapper
    return f(*args, **kwargs)
  File "/opt/anaconda3/envs/airflow_env/lib/python3.9/site-packages/airflow/cli/commands/task_command.py", line 483, in task_run
    task_return_code = _run_task_by_selected_method(args, _dag, ti)
  File "/opt/anaconda3/envs/airflow_env/lib/python3.9/site-packages/airflow/cli/commands/task_command.py", line 256, in _run_task_by_selected_method
    return _run_raw_task(args, ti)
  File "/opt/anaconda3/envs/airflow_env/lib/python3.9/site-packages/airflow/cli/commands/task_command.py", line 341, in _run_raw_task
    return ti._run_raw_task(
  File "/opt/anaconda3/envs/airflow_env/lib/python3.9/site-packages/airflow/utils/session.py", line 97, in wrapper
    return func(*args, session=session, **kwargs)
  File "/opt/anaconda3/envs/airflow_env/lib/python3.9/site-packages/airflow/models/taskinstance.py", line 3005, in _run_raw_task
    return _run_raw_task(
  File "/opt/anaconda3/envs/airflow_env/lib/python3.9/site-packages/airflow/models/taskinstance.py", line 273, in _run_raw_task
    TaskInstance._execute_task_with_callbacks(
  File "/opt/anaconda3/envs/airflow_env/lib/python3.9/site-packages/airflow/models/taskinstance.py", line 3159, in _execute_task_with_callbacks
    result = self._execute_task(context, task_orig)
  File "/opt/anaconda3/envs/airflow_env/lib/python3.9/site-packages/airflow/models/taskinstance.py", line 3183, in _execute_task
    return _execute_task(self, context, task_orig)
  File "/opt/anaconda3/envs/airflow_env/lib/python3.9/site-packages/airflow/models/taskinstance.py", line 767, in _execute_task
    result = _execute_callable(context=context, **execute_callable_kwargs)
  File "/opt/anaconda3/envs/airflow_env/lib/python3.9/site-packages/airflow/models/taskinstance.py", line 733, in _execute_callable
    return ExecutionCallableRunner(
  File "/opt/anaconda3/envs/airflow_env/lib/python3.9/site-packages/airflow/utils/operator_helpers.py", line 252, in run
    return self.func(*args, **kwargs)
  File "/opt/anaconda3/envs/airflow_env/lib/python3.9/site-packages/airflow/models/baseoperator.py", line 422, in wrapper
    return func(self, *args, **kwargs)
  File "/opt/anaconda3/envs/airflow_env/lib/python3.9/site-packages/airflow/operators/bash.py", line 276, in execute
    raise AirflowException(
airflow.exceptions.AirflowException: Bash command failed. The command returned a non-zero exit code 1.
[2025-01-04T10:38:56.025-0800] {local_task_job_runner.py:266} INFO - Task exited with return code 1
[2025-01-04T10:38:56.056-0800] {taskinstance.py:3895} INFO - 0 downstream tasks scheduled from follow-on schedule check
[2025-01-04T10:38:56.057-0800] {local_task_job_runner.py:245} INFO - ::endgroup::
