[2025-01-04T11:01:58.150-0800] {local_task_job_runner.py:123} INFO - ::group::Pre task execution logs
[2025-01-04T11:01:58.166-0800] {taskinstance.py:2613} INFO - Dependencies all met for dep_context=non-requeueable deps ti=<TaskInstance: CovidE2EPipeDag.stage_raw_data scheduled__2025-01-01T00:55:00+00:00 [queued]>
[2025-01-04T11:01:58.175-0800] {taskinstance.py:2613} INFO - Dependencies all met for dep_context=requeueable deps ti=<TaskInstance: CovidE2EPipeDag.stage_raw_data scheduled__2025-01-01T00:55:00+00:00 [queued]>
[2025-01-04T11:01:58.175-0800] {taskinstance.py:2866} INFO - Starting attempt 1 of 2
[2025-01-04T11:01:58.199-0800] {taskinstance.py:2889} INFO - Executing <Task(BashOperator): stage_raw_data> on 2025-01-01 00:55:00+00:00
[2025-01-04T11:01:58.202-0800] {standard_task_runner.py:72} INFO - Started process 75231 to run task
[2025-01-04T11:01:58.213-0800] {standard_task_runner.py:104} INFO - Running: ['airflow', 'tasks', 'run', 'CovidE2EPipeDag', 'stage_raw_data', 'scheduled__2025-01-01T00:55:00+00:00', '--job-id', '815', '--raw', '--subdir', 'DAGS_FOLDER/CovidE2EPipeDag.py', '--cfg-path', '/var/folders/vm/rn9v1g1j739_mq8j5pfl1yxm0000gn/T/tmphw26br1d']
[2025-01-04T11:01:58.216-0800] {standard_task_runner.py:105} INFO - Job 815: Subtask stage_raw_data
[2025-01-04T11:01:58.309-0800] {task_command.py:467} INFO - Running <TaskInstance: CovidE2EPipeDag.stage_raw_data scheduled__2025-01-01T00:55:00+00:00 [running]> on host Matthews-MacBook-Air.local
[2025-01-04T11:01:58.420-0800] {taskinstance.py:3132} INFO - Exporting env vars: AIRFLOW_CTX_DAG_OWNER='Matthew Horn' AIRFLOW_CTX_DAG_ID='CovidE2EPipeDag' AIRFLOW_CTX_TASK_ID='stage_raw_data' AIRFLOW_CTX_EXECUTION_DATE='2025-01-01T00:55:00+00:00' AIRFLOW_CTX_TRY_NUMBER='1' AIRFLOW_CTX_DAG_RUN_ID='scheduled__2025-01-01T00:55:00+00:00'
[2025-01-04T11:01:58.422-0800] {logging_mixin.py:190} INFO - Task instance is in running state
[2025-01-04T11:01:58.423-0800] {logging_mixin.py:190} INFO -  Previous state of the Task instance: queued
[2025-01-04T11:01:58.424-0800] {logging_mixin.py:190} INFO - Current task name:stage_raw_data state:running start_date:2025-01-04 19:01:58.167587+00:00
[2025-01-04T11:01:58.424-0800] {logging_mixin.py:190} INFO - Dag name:CovidE2EPipeDag and current dag run status:running
[2025-01-04T11:01:58.425-0800] {taskinstance.py:731} INFO - ::endgroup::
[2025-01-04T11:01:58.427-0800] {subprocess.py:78} INFO - Tmp dir root location: /var/folders/vm/rn9v1g1j739_mq8j5pfl1yxm0000gn/T
[2025-01-04T11:01:58.428-0800] {subprocess.py:88} INFO - Running command: ['/bin/bash', '-c', 'snow stage copy ~/airflow/data/raw/industrial_production_{ ds }.csv @CovidE2EPipeline.raw_data.raw_data_stage']
[2025-01-04T11:01:58.438-0800] {subprocess.py:99} INFO - Output:
[2025-01-04T11:02:00.699-0800] {local_task_job_runner.py:245} INFO - ::endgroup::
[2025-01-04T11:02:00.716-0800] {process_utils.py:132} INFO - Sending 15 to group 75231. PIDs of all processes in the group: [75232, 75231]
[2025-01-04T11:02:00.718-0800] {process_utils.py:87} INFO - Sending the signal 15 to group 75231
[2025-01-04T11:02:00.719-0800] {taskinstance.py:3093} ERROR - Received SIGTERM. Terminating subprocesses.
[2025-01-04T11:02:00.721-0800] {subprocess.py:117} INFO - Sending SIGTERM signal to process group
[2025-01-04T11:02:00.751-0800] {taskinstance.py:3311} ERROR - Task failed with exception
Traceback (most recent call last):
  File "/opt/anaconda3/envs/airflow_env/lib/python3.9/site-packages/airflow/models/taskinstance.py", line 767, in _execute_task
    result = _execute_callable(context=context, **execute_callable_kwargs)
  File "/opt/anaconda3/envs/airflow_env/lib/python3.9/site-packages/airflow/models/taskinstance.py", line 733, in _execute_callable
    return ExecutionCallableRunner(
  File "/opt/anaconda3/envs/airflow_env/lib/python3.9/site-packages/airflow/utils/operator_helpers.py", line 252, in run
    return self.func(*args, **kwargs)
  File "/opt/anaconda3/envs/airflow_env/lib/python3.9/site-packages/airflow/models/baseoperator.py", line 422, in wrapper
    return func(self, *args, **kwargs)
  File "/opt/anaconda3/envs/airflow_env/lib/python3.9/site-packages/airflow/operators/bash.py", line 257, in execute
    result = self._run_inline_command(bash_path=bash_path, env=env)
  File "/opt/anaconda3/envs/airflow_env/lib/python3.9/site-packages/airflow/operators/bash.py", line 284, in _run_inline_command
    return self.subprocess_hook.run_command(
  File "/opt/anaconda3/envs/airflow_env/lib/python3.9/site-packages/airflow/hooks/subprocess.py", line 104, in run_command
    for raw_line in iter(self.sub_process.stdout.readline, b""):
  File "/opt/anaconda3/envs/airflow_env/lib/python3.9/site-packages/airflow/models/taskinstance.py", line 3095, in signal_handler
    raise AirflowTaskTerminated("Task received SIGTERM signal")
airflow.exceptions.AirflowTaskTerminated: Task received SIGTERM signal
[2025-01-04T11:02:00.774-0800] {logging_mixin.py:190} INFO - Task instance in failure state
[2025-01-04T11:02:00.776-0800] {logging_mixin.py:190} INFO - Task start:2025-01-04 19:01:58.167587+00:00 end:2025-01-04 19:02:00.773685+00:00 duration:2.606098
[2025-01-04T11:02:00.777-0800] {logging_mixin.py:190} INFO - Task:<Task(BashOperator): stage_raw_data> dag:<DAG: CovidE2EPipeDag> dagrun:<DagRun CovidE2EPipeDag @ 2025-01-01 00:55:00+00:00: scheduled__2025-01-01T00:55:00+00:00, state:running, queued_at: 2025-01-04 18:38:29.229009+00:00. externally triggered: False>
[2025-01-04T11:02:00.779-0800] {logging_mixin.py:190} INFO - Failure caused by Task received SIGTERM signal
[2025-01-04T11:02:00.781-0800] {taskinstance.py:1225} INFO - Marking task as UP_FOR_RETRY. dag_id=CovidE2EPipeDag, task_id=stage_raw_data, run_id=scheduled__2025-01-01T00:55:00+00:00, execution_date=20250101T005500, start_date=20250104T190158, end_date=20250104T190200
[2025-01-04T11:02:00.842-0800] {taskinstance.py:340} INFO - ::group::Post task execution logs
[2025-01-04T11:02:00.865-0800] {process_utils.py:80} INFO - Process psutil.Process(pid=75231, status='terminated', exitcode=2, started='11:01:58') (75231) terminated with exit code 2
[2025-01-04T11:02:00.868-0800] {process_utils.py:80} INFO - Process psutil.Process(pid=75232, status='terminated', started='11:01:58') (75232) terminated with exit code None
