[2025-01-04T10:30:51.466-0800] {local_task_job_runner.py:123} INFO - ::group::Pre task execution logs
[2025-01-04T10:30:51.481-0800] {taskinstance.py:2613} INFO - Dependencies all met for dep_context=non-requeueable deps ti=<TaskInstance: CovidE2EPipeDag.stage_raw_data scheduled__2025-01-01T00:50:00+00:00 [queued]>
[2025-01-04T10:30:51.489-0800] {taskinstance.py:2613} INFO - Dependencies all met for dep_context=requeueable deps ti=<TaskInstance: CovidE2EPipeDag.stage_raw_data scheduled__2025-01-01T00:50:00+00:00 [queued]>
[2025-01-04T10:30:51.489-0800] {taskinstance.py:2866} INFO - Starting attempt 2 of 2
[2025-01-04T10:30:51.511-0800] {taskinstance.py:2889} INFO - Executing <Task(BashOperator): stage_raw_data> on 2025-01-01 00:50:00+00:00
[2025-01-04T10:30:51.515-0800] {standard_task_runner.py:72} INFO - Started process 73979 to run task
[2025-01-04T10:30:51.525-0800] {standard_task_runner.py:104} INFO - Running: ['airflow', 'tasks', 'run', 'CovidE2EPipeDag', 'stage_raw_data', 'scheduled__2025-01-01T00:50:00+00:00', '--job-id', '771', '--raw', '--subdir', 'DAGS_FOLDER/CovidE2EPipeDag.py', '--cfg-path', '/var/folders/vm/rn9v1g1j739_mq8j5pfl1yxm0000gn/T/tmpz6gc2b76']
[2025-01-04T10:30:51.529-0800] {standard_task_runner.py:105} INFO - Job 771: Subtask stage_raw_data
[2025-01-04T10:30:51.589-0800] {task_command.py:467} INFO - Running <TaskInstance: CovidE2EPipeDag.stage_raw_data scheduled__2025-01-01T00:50:00+00:00 [running]> on host Matthews-MacBook-Air.local
[2025-01-04T10:30:51.682-0800] {taskinstance.py:3132} INFO - Exporting env vars: AIRFLOW_CTX_DAG_OWNER='Matthew Horn' AIRFLOW_CTX_DAG_ID='CovidE2EPipeDag' AIRFLOW_CTX_TASK_ID='stage_raw_data' AIRFLOW_CTX_EXECUTION_DATE='2025-01-01T00:50:00+00:00' AIRFLOW_CTX_TRY_NUMBER='2' AIRFLOW_CTX_DAG_RUN_ID='scheduled__2025-01-01T00:50:00+00:00'
[2025-01-04T10:30:51.687-0800] {logging_mixin.py:190} INFO - Task instance is in running state
[2025-01-04T10:30:51.689-0800] {logging_mixin.py:190} INFO -  Previous state of the Task instance: queued
[2025-01-04T10:30:51.690-0800] {logging_mixin.py:190} INFO - Current task name:stage_raw_data state:running start_date:2025-01-04 18:30:51.482039+00:00
[2025-01-04T10:30:51.692-0800] {logging_mixin.py:190} INFO - Dag name:CovidE2EPipeDag and current dag run status:running
[2025-01-04T10:30:51.694-0800] {taskinstance.py:731} INFO - ::endgroup::
[2025-01-04T10:30:51.696-0800] {subprocess.py:78} INFO - Tmp dir root location: /var/folders/vm/rn9v1g1j739_mq8j5pfl1yxm0000gn/T
[2025-01-04T10:30:51.698-0800] {subprocess.py:88} INFO - Running command: ['/bin/bash', '-c', 'snow stage copy ~/airflow/data/raw/industrial_production_2025-01-04.csv @CovidE2EPipeline.raw_data.raw_data_stage']
[2025-01-04T10:30:51.712-0800] {subprocess.py:99} INFO - Output:
[2025-01-04T10:30:55.631-0800] {subprocess.py:106} INFO - 
[2025-01-04T10:30:55.634-0800] {subprocess.py:106} INFO - An unexpected exception occurred. Use --debug option to see the traceback. Exception message:
[2025-01-04T10:30:55.637-0800] {subprocess.py:106} INFO - 
[2025-01-04T10:30:55.638-0800] {subprocess.py:106} INFO - 002003 (02000): 01b97dd6-0004-6978-0003-5bfb0002011e: SQL compilation error:
[2025-01-04T10:30:55.640-0800] {subprocess.py:106} INFO - Database 'COVIDE2EPIPELINE' does not exist or not authorized.
[2025-01-04T10:30:56.084-0800] {subprocess.py:110} INFO - Command exited with return code 1
[2025-01-04T10:30:56.099-0800] {taskinstance.py:3311} ERROR - Task failed with exception
Traceback (most recent call last):
  File "/opt/anaconda3/envs/airflow_env/lib/python3.9/site-packages/airflow/models/taskinstance.py", line 767, in _execute_task
    result = _execute_callable(context=context, **execute_callable_kwargs)
  File "/opt/anaconda3/envs/airflow_env/lib/python3.9/site-packages/airflow/models/taskinstance.py", line 733, in _execute_callable
    return ExecutionCallableRunner(
  File "/opt/anaconda3/envs/airflow_env/lib/python3.9/site-packages/airflow/utils/operator_helpers.py", line 252, in run
    return self.func(*args, **kwargs)
  File "/opt/anaconda3/envs/airflow_env/lib/python3.9/site-packages/airflow/models/baseoperator.py", line 422, in wrapper
    return func(self, *args, **kwargs)
  File "/opt/anaconda3/envs/airflow_env/lib/python3.9/site-packages/airflow/operators/bash.py", line 276, in execute
    raise AirflowException(
airflow.exceptions.AirflowException: Bash command failed. The command returned a non-zero exit code 1.
[2025-01-04T10:30:56.105-0800] {logging_mixin.py:190} INFO - Task instance in failure state
[2025-01-04T10:30:56.106-0800] {logging_mixin.py:190} INFO - Task start:2025-01-04 18:30:51.482039+00:00 end:2025-01-04 18:30:56.104218+00:00 duration:4.622179
[2025-01-04T10:30:56.107-0800] {logging_mixin.py:190} INFO - Task:<Task(BashOperator): stage_raw_data> dag:<DAG: CovidE2EPipeDag> dagrun:<DagRun CovidE2EPipeDag @ 2025-01-01 00:50:00+00:00: scheduled__2025-01-01T00:50:00+00:00, state:running, queued_at: 2025-01-04 06:57:41.956679+00:00. externally triggered: False>
[2025-01-04T10:30:56.108-0800] {logging_mixin.py:190} INFO - Failure caused by Bash command failed. The command returned a non-zero exit code 1.
[2025-01-04T10:30:56.110-0800] {taskinstance.py:1225} INFO - Marking task as FAILED. dag_id=CovidE2EPipeDag, task_id=stage_raw_data, run_id=scheduled__2025-01-01T00:50:00+00:00, execution_date=20250101T005000, start_date=20250104T183051, end_date=20250104T183056
[2025-01-04T10:30:56.124-0800] {taskinstance.py:340} INFO - ::group::Post task execution logs
[2025-01-04T10:30:56.127-0800] {standard_task_runner.py:124} ERROR - Failed to execute job 771 for task stage_raw_data (Bash command failed. The command returned a non-zero exit code 1.; 73979)
Traceback (most recent call last):
  File "/opt/anaconda3/envs/airflow_env/lib/python3.9/site-packages/airflow/task/task_runner/standard_task_runner.py", line 117, in _start_by_fork
    ret = args.func(args, dag=self.dag)
  File "/opt/anaconda3/envs/airflow_env/lib/python3.9/site-packages/airflow/cli/cli_config.py", line 49, in command
    return func(*args, **kwargs)
  File "/opt/anaconda3/envs/airflow_env/lib/python3.9/site-packages/airflow/utils/cli.py", line 116, in wrapper
    return f(*args, **kwargs)
  File "/opt/anaconda3/envs/airflow_env/lib/python3.9/site-packages/airflow/cli/commands/task_command.py", line 483, in task_run
    task_return_code = _run_task_by_selected_method(args, _dag, ti)
  File "/opt/anaconda3/envs/airflow_env/lib/python3.9/site-packages/airflow/cli/commands/task_command.py", line 256, in _run_task_by_selected_method
    return _run_raw_task(args, ti)
  File "/opt/anaconda3/envs/airflow_env/lib/python3.9/site-packages/airflow/cli/commands/task_command.py", line 341, in _run_raw_task
    return ti._run_raw_task(
  File "/opt/anaconda3/envs/airflow_env/lib/python3.9/site-packages/airflow/utils/session.py", line 97, in wrapper
    return func(*args, session=session, **kwargs)
  File "/opt/anaconda3/envs/airflow_env/lib/python3.9/site-packages/airflow/models/taskinstance.py", line 3005, in _run_raw_task
    return _run_raw_task(
  File "/opt/anaconda3/envs/airflow_env/lib/python3.9/site-packages/airflow/models/taskinstance.py", line 273, in _run_raw_task
    TaskInstance._execute_task_with_callbacks(
  File "/opt/anaconda3/envs/airflow_env/lib/python3.9/site-packages/airflow/models/taskinstance.py", line 3159, in _execute_task_with_callbacks
    result = self._execute_task(context, task_orig)
  File "/opt/anaconda3/envs/airflow_env/lib/python3.9/site-packages/airflow/models/taskinstance.py", line 3183, in _execute_task
    return _execute_task(self, context, task_orig)
  File "/opt/anaconda3/envs/airflow_env/lib/python3.9/site-packages/airflow/models/taskinstance.py", line 767, in _execute_task
    result = _execute_callable(context=context, **execute_callable_kwargs)
  File "/opt/anaconda3/envs/airflow_env/lib/python3.9/site-packages/airflow/models/taskinstance.py", line 733, in _execute_callable
    return ExecutionCallableRunner(
  File "/opt/anaconda3/envs/airflow_env/lib/python3.9/site-packages/airflow/utils/operator_helpers.py", line 252, in run
    return self.func(*args, **kwargs)
  File "/opt/anaconda3/envs/airflow_env/lib/python3.9/site-packages/airflow/models/baseoperator.py", line 422, in wrapper
    return func(self, *args, **kwargs)
  File "/opt/anaconda3/envs/airflow_env/lib/python3.9/site-packages/airflow/operators/bash.py", line 276, in execute
    raise AirflowException(
airflow.exceptions.AirflowException: Bash command failed. The command returned a non-zero exit code 1.
[2025-01-04T10:30:56.145-0800] {local_task_job_runner.py:266} INFO - Task exited with return code 1
[2025-01-04T10:30:56.173-0800] {taskinstance.py:3895} INFO - 0 downstream tasks scheduled from follow-on schedule check
[2025-01-04T10:30:56.174-0800] {local_task_job_runner.py:245} INFO - ::endgroup::
