[2025-01-03T21:04:07.388-0800] {local_task_job_runner.py:123} INFO - ::group::Pre task execution logs
[2025-01-03T21:04:07.423-0800] {taskinstance.py:2613} INFO - Dependencies all met for dep_context=non-requeueable deps ti=<TaskInstance: CovidE2EPipeDag.stage_raw_data scheduled__2025-01-01T00:21:00+00:00 [queued]>
[2025-01-03T21:04:07.436-0800] {taskinstance.py:2613} INFO - Dependencies all met for dep_context=requeueable deps ti=<TaskInstance: CovidE2EPipeDag.stage_raw_data scheduled__2025-01-01T00:21:00+00:00 [queued]>
[2025-01-03T21:04:07.436-0800] {taskinstance.py:2866} INFO - Starting attempt 2 of 2
[2025-01-03T21:04:07.457-0800] {taskinstance.py:2889} INFO - Executing <Task(BashOperator): stage_raw_data> on 2025-01-01 00:21:00+00:00
[2025-01-03T21:04:07.470-0800] {standard_task_runner.py:72} INFO - Started process 69037 to run task
[2025-01-03T21:04:07.474-0800] {standard_task_runner.py:104} INFO - Running: ['airflow', 'tasks', 'run', 'CovidE2EPipeDag', 'stage_raw_data', 'scheduled__2025-01-01T00:21:00+00:00', '--job-id', '489', '--raw', '--subdir', 'DAGS_FOLDER/CovidE2EPipeDag.py', '--cfg-path', '/var/folders/vm/rn9v1g1j739_mq8j5pfl1yxm0000gn/T/tmpg5nv94io']
[2025-01-03T21:04:07.477-0800] {standard_task_runner.py:105} INFO - Job 489: Subtask stage_raw_data
[2025-01-03T21:04:07.555-0800] {task_command.py:467} INFO - Running <TaskInstance: CovidE2EPipeDag.stage_raw_data scheduled__2025-01-01T00:21:00+00:00 [running]> on host Matthews-MacBook-Air.local
[2025-01-03T21:04:07.676-0800] {taskinstance.py:3132} INFO - Exporting env vars: AIRFLOW_CTX_DAG_OWNER='Matthew Horn' AIRFLOW_CTX_DAG_ID='CovidE2EPipeDag' AIRFLOW_CTX_TASK_ID='stage_raw_data' AIRFLOW_CTX_EXECUTION_DATE='2025-01-01T00:21:00+00:00' AIRFLOW_CTX_TRY_NUMBER='2' AIRFLOW_CTX_DAG_RUN_ID='scheduled__2025-01-01T00:21:00+00:00'
[2025-01-03T21:04:07.685-0800] {logging_mixin.py:190} INFO - Task instance is in running state
[2025-01-03T21:04:07.685-0800] {logging_mixin.py:190} INFO -  Previous state of the Task instance: queued
[2025-01-03T21:04:07.686-0800] {logging_mixin.py:190} INFO - Current task name:stage_raw_data state:running start_date:2025-01-04 05:04:07.423964+00:00
[2025-01-03T21:04:07.687-0800] {logging_mixin.py:190} INFO - Dag name:CovidE2EPipeDag and current dag run status:running
[2025-01-03T21:04:07.688-0800] {taskinstance.py:731} INFO - ::endgroup::
[2025-01-03T21:04:07.690-0800] {subprocess.py:78} INFO - Tmp dir root location: /var/folders/vm/rn9v1g1j739_mq8j5pfl1yxm0000gn/T
[2025-01-03T21:04:07.691-0800] {subprocess.py:88} INFO - Running command: ['/bin/bash', '-c', 'snow stage copy ~/airflow/data/raw/industrial_production_2025-01-03.csv @raw_data_stage']
[2025-01-03T21:04:07.703-0800] {subprocess.py:99} INFO - Output:
[2025-01-03T21:04:13.418-0800] {subprocess.py:106} INFO - 
[2025-01-03T21:04:13.420-0800] {subprocess.py:106} INFO - An unexpected exception occurred. Use --debug option to see the traceback. Exception message:
[2025-01-03T21:04:13.422-0800] {subprocess.py:106} INFO - 
[2025-01-03T21:04:13.423-0800] {subprocess.py:106} INFO - 090106 (22000): 01b97ab0-0004-5b35-0003-5bfb00016f36: Cannot perform STAGE PUT. This session does not have a current schema. Call 'USE SCHEMA', or use a qualified name.
[2025-01-03T21:04:13.942-0800] {subprocess.py:110} INFO - Command exited with return code 1
[2025-01-03T21:04:13.960-0800] {taskinstance.py:3311} ERROR - Task failed with exception
Traceback (most recent call last):
  File "/opt/anaconda3/envs/airflow_env/lib/python3.9/site-packages/airflow/models/taskinstance.py", line 767, in _execute_task
    result = _execute_callable(context=context, **execute_callable_kwargs)
  File "/opt/anaconda3/envs/airflow_env/lib/python3.9/site-packages/airflow/models/taskinstance.py", line 733, in _execute_callable
    return ExecutionCallableRunner(
  File "/opt/anaconda3/envs/airflow_env/lib/python3.9/site-packages/airflow/utils/operator_helpers.py", line 252, in run
    return self.func(*args, **kwargs)
  File "/opt/anaconda3/envs/airflow_env/lib/python3.9/site-packages/airflow/models/baseoperator.py", line 422, in wrapper
    return func(self, *args, **kwargs)
  File "/opt/anaconda3/envs/airflow_env/lib/python3.9/site-packages/airflow/operators/bash.py", line 276, in execute
    raise AirflowException(
airflow.exceptions.AirflowException: Bash command failed. The command returned a non-zero exit code 1.
[2025-01-03T21:04:13.973-0800] {logging_mixin.py:190} INFO - Task instance in failure state
[2025-01-03T21:04:13.974-0800] {logging_mixin.py:190} INFO - Task start:2025-01-04 05:04:07.423964+00:00 end:2025-01-04 05:04:13.972996+00:00 duration:6.549032
[2025-01-03T21:04:13.975-0800] {logging_mixin.py:190} INFO - Task:<Task(BashOperator): stage_raw_data> dag:<DAG: CovidE2EPipeDag> dagrun:<DagRun CovidE2EPipeDag @ 2025-01-01 00:21:00+00:00: scheduled__2025-01-01T00:21:00+00:00, state:running, queued_at: 2025-01-04 04:53:53.807155+00:00. externally triggered: False>
[2025-01-03T21:04:13.976-0800] {logging_mixin.py:190} INFO - Failure caused by Bash command failed. The command returned a non-zero exit code 1.
[2025-01-03T21:04:13.977-0800] {taskinstance.py:1225} INFO - Marking task as FAILED. dag_id=CovidE2EPipeDag, task_id=stage_raw_data, run_id=scheduled__2025-01-01T00:21:00+00:00, execution_date=20250101T002100, start_date=20250104T050407, end_date=20250104T050413
[2025-01-03T21:04:14.000-0800] {taskinstance.py:340} INFO - ::group::Post task execution logs
[2025-01-03T21:04:14.002-0800] {standard_task_runner.py:124} ERROR - Failed to execute job 489 for task stage_raw_data (Bash command failed. The command returned a non-zero exit code 1.; 69037)
Traceback (most recent call last):
  File "/opt/anaconda3/envs/airflow_env/lib/python3.9/site-packages/airflow/task/task_runner/standard_task_runner.py", line 117, in _start_by_fork
    ret = args.func(args, dag=self.dag)
  File "/opt/anaconda3/envs/airflow_env/lib/python3.9/site-packages/airflow/cli/cli_config.py", line 49, in command
    return func(*args, **kwargs)
  File "/opt/anaconda3/envs/airflow_env/lib/python3.9/site-packages/airflow/utils/cli.py", line 116, in wrapper
    return f(*args, **kwargs)
  File "/opt/anaconda3/envs/airflow_env/lib/python3.9/site-packages/airflow/cli/commands/task_command.py", line 483, in task_run
    task_return_code = _run_task_by_selected_method(args, _dag, ti)
  File "/opt/anaconda3/envs/airflow_env/lib/python3.9/site-packages/airflow/cli/commands/task_command.py", line 256, in _run_task_by_selected_method
    return _run_raw_task(args, ti)
  File "/opt/anaconda3/envs/airflow_env/lib/python3.9/site-packages/airflow/cli/commands/task_command.py", line 341, in _run_raw_task
    return ti._run_raw_task(
  File "/opt/anaconda3/envs/airflow_env/lib/python3.9/site-packages/airflow/utils/session.py", line 97, in wrapper
    return func(*args, session=session, **kwargs)
  File "/opt/anaconda3/envs/airflow_env/lib/python3.9/site-packages/airflow/models/taskinstance.py", line 3005, in _run_raw_task
    return _run_raw_task(
  File "/opt/anaconda3/envs/airflow_env/lib/python3.9/site-packages/airflow/models/taskinstance.py", line 273, in _run_raw_task
    TaskInstance._execute_task_with_callbacks(
  File "/opt/anaconda3/envs/airflow_env/lib/python3.9/site-packages/airflow/models/taskinstance.py", line 3159, in _execute_task_with_callbacks
    result = self._execute_task(context, task_orig)
  File "/opt/anaconda3/envs/airflow_env/lib/python3.9/site-packages/airflow/models/taskinstance.py", line 3183, in _execute_task
    return _execute_task(self, context, task_orig)
  File "/opt/anaconda3/envs/airflow_env/lib/python3.9/site-packages/airflow/models/taskinstance.py", line 767, in _execute_task
    result = _execute_callable(context=context, **execute_callable_kwargs)
  File "/opt/anaconda3/envs/airflow_env/lib/python3.9/site-packages/airflow/models/taskinstance.py", line 733, in _execute_callable
    return ExecutionCallableRunner(
  File "/opt/anaconda3/envs/airflow_env/lib/python3.9/site-packages/airflow/utils/operator_helpers.py", line 252, in run
    return self.func(*args, **kwargs)
  File "/opt/anaconda3/envs/airflow_env/lib/python3.9/site-packages/airflow/models/baseoperator.py", line 422, in wrapper
    return func(self, *args, **kwargs)
  File "/opt/anaconda3/envs/airflow_env/lib/python3.9/site-packages/airflow/operators/bash.py", line 276, in execute
    raise AirflowException(
airflow.exceptions.AirflowException: Bash command failed. The command returned a non-zero exit code 1.
[2025-01-03T21:04:14.030-0800] {local_task_job_runner.py:266} INFO - Task exited with return code 1
[2025-01-03T21:04:14.065-0800] {taskinstance.py:3895} INFO - 0 downstream tasks scheduled from follow-on schedule check
[2025-01-03T21:04:14.067-0800] {local_task_job_runner.py:245} INFO - ::endgroup::
