[2025-01-03T19:58:20.882-0800] {local_task_job_runner.py:123} INFO - ::group::Pre task execution logs
[2025-01-03T19:58:20.925-0800] {taskinstance.py:2613} INFO - Dependencies all met for dep_context=non-requeueable deps ti=<TaskInstance: CovidE2EPipeDag.stage_raw_data manual__2025-01-04T03:43:50.842530+00:00 [queued]>
[2025-01-03T19:58:20.952-0800] {taskinstance.py:2613} INFO - Dependencies all met for dep_context=requeueable deps ti=<TaskInstance: CovidE2EPipeDag.stage_raw_data manual__2025-01-04T03:43:50.842530+00:00 [queued]>
[2025-01-03T19:58:20.954-0800] {taskinstance.py:2866} INFO - Starting attempt 1 of 2
[2025-01-03T19:58:21.014-0800] {taskinstance.py:2889} INFO - Executing <Task(BashOperator): stage_raw_data> on 2025-01-04 03:43:50.842530+00:00
[2025-01-03T19:58:21.058-0800] {standard_task_runner.py:104} INFO - Running: ['airflow', 'tasks', 'run', 'CovidE2EPipeDag', 'stage_raw_data', 'manual__2025-01-04T03:43:50.842530+00:00', '--job-id', '295', '--raw', '--subdir', 'DAGS_FOLDER/CovidE2EPipeDag.py', '--cfg-path', '/var/folders/vm/rn9v1g1j739_mq8j5pfl1yxm0000gn/T/tmpy84hyo2k']
[2025-01-03T19:58:21.062-0800] {standard_task_runner.py:105} INFO - Job 295: Subtask stage_raw_data
[2025-01-03T19:58:21.061-0800] {standard_task_runner.py:72} INFO - Started process 66074 to run task
[2025-01-03T19:58:21.163-0800] {task_command.py:467} INFO - Running <TaskInstance: CovidE2EPipeDag.stage_raw_data manual__2025-01-04T03:43:50.842530+00:00 [running]> on host Matthews-MacBook-Air.local
[2025-01-03T19:58:21.417-0800] {taskinstance.py:3132} INFO - Exporting env vars: AIRFLOW_CTX_DAG_OWNER='Matthew Horn' AIRFLOW_CTX_DAG_ID='CovidE2EPipeDag' AIRFLOW_CTX_TASK_ID='stage_raw_data' AIRFLOW_CTX_EXECUTION_DATE='2025-01-04T03:43:50.842530+00:00' AIRFLOW_CTX_TRY_NUMBER='1' AIRFLOW_CTX_DAG_RUN_ID='manual__2025-01-04T03:43:50.842530+00:00'
[2025-01-03T19:58:21.422-0800] {logging_mixin.py:190} INFO - Task instance is in running state
[2025-01-03T19:58:21.425-0800] {logging_mixin.py:190} INFO -  Previous state of the Task instance: queued
[2025-01-03T19:58:21.426-0800] {logging_mixin.py:190} INFO - Current task name:stage_raw_data state:running start_date:2025-01-04 03:58:20.926240+00:00
[2025-01-03T19:58:21.428-0800] {logging_mixin.py:190} INFO - Dag name:CovidE2EPipeDag and current dag run status:running
[2025-01-03T19:58:21.432-0800] {taskinstance.py:731} INFO - ::endgroup::
[2025-01-03T19:58:21.435-0800] {subprocess.py:78} INFO - Tmp dir root location: /var/folders/vm/rn9v1g1j739_mq8j5pfl1yxm0000gn/T
[2025-01-03T19:58:21.439-0800] {subprocess.py:88} INFO - Running command: ['/bin/bash', '-c', 'snow stage copy ~/airflow/data/raw/industrial_production_2025-01-03.csv @raw_data_stage']
[2025-01-03T19:58:21.472-0800] {subprocess.py:99} INFO - Output:
[2025-01-03T19:58:31.300-0800] {subprocess.py:106} INFO - 
[2025-01-03T19:58:31.303-0800] {subprocess.py:106} INFO - An unexpected exception occurred. Use --debug option to see the traceback. Exception message:
[2025-01-03T19:58:31.304-0800] {subprocess.py:106} INFO - 
[2025-01-03T19:58:31.306-0800] {subprocess.py:106} INFO - 090106 (22000): 01b97a6e-0004-5b31-0003-5bfb0001f7e2: Cannot perform STAGE PUT. This session does not have a current schema. Call 'USE SCHEMA', or use a qualified name.
[2025-01-03T19:58:32.133-0800] {subprocess.py:110} INFO - Command exited with return code 1
[2025-01-03T19:58:32.155-0800] {taskinstance.py:3311} ERROR - Task failed with exception
Traceback (most recent call last):
  File "/opt/anaconda3/envs/airflow_env/lib/python3.9/site-packages/airflow/models/taskinstance.py", line 767, in _execute_task
    result = _execute_callable(context=context, **execute_callable_kwargs)
  File "/opt/anaconda3/envs/airflow_env/lib/python3.9/site-packages/airflow/models/taskinstance.py", line 733, in _execute_callable
    return ExecutionCallableRunner(
  File "/opt/anaconda3/envs/airflow_env/lib/python3.9/site-packages/airflow/utils/operator_helpers.py", line 252, in run
    return self.func(*args, **kwargs)
  File "/opt/anaconda3/envs/airflow_env/lib/python3.9/site-packages/airflow/models/baseoperator.py", line 422, in wrapper
    return func(self, *args, **kwargs)
  File "/opt/anaconda3/envs/airflow_env/lib/python3.9/site-packages/airflow/operators/bash.py", line 276, in execute
    raise AirflowException(
airflow.exceptions.AirflowException: Bash command failed. The command returned a non-zero exit code 1.
[2025-01-03T19:58:32.179-0800] {logging_mixin.py:190} INFO - Task instance in failure state
[2025-01-03T19:58:32.184-0800] {logging_mixin.py:190} INFO - Task start:2025-01-04 03:58:20.926240+00:00 end:2025-01-04 03:58:32.177935+00:00 duration:11.251695
[2025-01-03T19:58:32.186-0800] {logging_mixin.py:190} INFO - Task:<Task(BashOperator): stage_raw_data> dag:<DAG: CovidE2EPipeDag> dagrun:<DagRun CovidE2EPipeDag @ 2025-01-04 03:43:50.842530+00:00: manual__2025-01-04T03:43:50.842530+00:00, state:running, queued_at: 2025-01-04 03:43:50.882817+00:00. externally triggered: True>
[2025-01-03T19:58:32.188-0800] {logging_mixin.py:190} INFO - Failure caused by Bash command failed. The command returned a non-zero exit code 1.
[2025-01-03T19:58:32.191-0800] {taskinstance.py:1225} INFO - Marking task as UP_FOR_RETRY. dag_id=CovidE2EPipeDag, task_id=stage_raw_data, run_id=manual__2025-01-04T03:43:50.842530+00:00, execution_date=20250104T034350, start_date=20250104T035820, end_date=20250104T035832
[2025-01-03T19:58:32.239-0800] {taskinstance.py:340} INFO - ::group::Post task execution logs
[2025-01-03T19:58:32.241-0800] {standard_task_runner.py:124} ERROR - Failed to execute job 295 for task stage_raw_data (Bash command failed. The command returned a non-zero exit code 1.; 66074)
Traceback (most recent call last):
  File "/opt/anaconda3/envs/airflow_env/lib/python3.9/site-packages/airflow/task/task_runner/standard_task_runner.py", line 117, in _start_by_fork
    ret = args.func(args, dag=self.dag)
  File "/opt/anaconda3/envs/airflow_env/lib/python3.9/site-packages/airflow/cli/cli_config.py", line 49, in command
    return func(*args, **kwargs)
  File "/opt/anaconda3/envs/airflow_env/lib/python3.9/site-packages/airflow/utils/cli.py", line 116, in wrapper
    return f(*args, **kwargs)
  File "/opt/anaconda3/envs/airflow_env/lib/python3.9/site-packages/airflow/cli/commands/task_command.py", line 483, in task_run
    task_return_code = _run_task_by_selected_method(args, _dag, ti)
  File "/opt/anaconda3/envs/airflow_env/lib/python3.9/site-packages/airflow/cli/commands/task_command.py", line 256, in _run_task_by_selected_method
    return _run_raw_task(args, ti)
  File "/opt/anaconda3/envs/airflow_env/lib/python3.9/site-packages/airflow/cli/commands/task_command.py", line 341, in _run_raw_task
    return ti._run_raw_task(
  File "/opt/anaconda3/envs/airflow_env/lib/python3.9/site-packages/airflow/utils/session.py", line 97, in wrapper
    return func(*args, session=session, **kwargs)
  File "/opt/anaconda3/envs/airflow_env/lib/python3.9/site-packages/airflow/models/taskinstance.py", line 3005, in _run_raw_task
    return _run_raw_task(
  File "/opt/anaconda3/envs/airflow_env/lib/python3.9/site-packages/airflow/models/taskinstance.py", line 273, in _run_raw_task
    TaskInstance._execute_task_with_callbacks(
  File "/opt/anaconda3/envs/airflow_env/lib/python3.9/site-packages/airflow/models/taskinstance.py", line 3159, in _execute_task_with_callbacks
    result = self._execute_task(context, task_orig)
  File "/opt/anaconda3/envs/airflow_env/lib/python3.9/site-packages/airflow/models/taskinstance.py", line 3183, in _execute_task
    return _execute_task(self, context, task_orig)
  File "/opt/anaconda3/envs/airflow_env/lib/python3.9/site-packages/airflow/models/taskinstance.py", line 767, in _execute_task
    result = _execute_callable(context=context, **execute_callable_kwargs)
  File "/opt/anaconda3/envs/airflow_env/lib/python3.9/site-packages/airflow/models/taskinstance.py", line 733, in _execute_callable
    return ExecutionCallableRunner(
  File "/opt/anaconda3/envs/airflow_env/lib/python3.9/site-packages/airflow/utils/operator_helpers.py", line 252, in run
    return self.func(*args, **kwargs)
  File "/opt/anaconda3/envs/airflow_env/lib/python3.9/site-packages/airflow/models/baseoperator.py", line 422, in wrapper
    return func(self, *args, **kwargs)
  File "/opt/anaconda3/envs/airflow_env/lib/python3.9/site-packages/airflow/operators/bash.py", line 276, in execute
    raise AirflowException(
airflow.exceptions.AirflowException: Bash command failed. The command returned a non-zero exit code 1.
[2025-01-03T19:58:32.282-0800] {local_task_job_runner.py:266} INFO - Task exited with return code 1
[2025-01-03T19:58:32.334-0800] {taskinstance.py:3895} INFO - 0 downstream tasks scheduled from follow-on schedule check
[2025-01-03T19:58:32.336-0800] {local_task_job_runner.py:245} INFO - ::endgroup::
