[2025-01-03T21:44:47.646-0800] {local_task_job_runner.py:123} INFO - ::group::Pre task execution logs
[2025-01-03T21:44:47.670-0800] {taskinstance.py:2613} INFO - Dependencies all met for dep_context=non-requeueable deps ti=<TaskInstance: CovidE2EPipeDag.insert_staged_raw_data scheduled__2025-01-01T00:34:00+00:00 [queued]>
[2025-01-03T21:44:47.682-0800] {taskinstance.py:2613} INFO - Dependencies all met for dep_context=requeueable deps ti=<TaskInstance: CovidE2EPipeDag.insert_staged_raw_data scheduled__2025-01-01T00:34:00+00:00 [queued]>
[2025-01-03T21:44:47.683-0800] {taskinstance.py:2866} INFO - Starting attempt 2 of 2
[2025-01-03T21:44:47.711-0800] {taskinstance.py:2889} INFO - Executing <Task(BashOperator): insert_staged_raw_data> on 2025-01-01 00:34:00+00:00
[2025-01-03T21:44:47.715-0800] {standard_task_runner.py:72} INFO - Started process 70917 to run task
[2025-01-03T21:44:47.729-0800] {standard_task_runner.py:104} INFO - Running: ['airflow', 'tasks', 'run', 'CovidE2EPipeDag', 'insert_staged_raw_data', 'scheduled__2025-01-01T00:34:00+00:00', '--job-id', '611', '--raw', '--subdir', 'DAGS_FOLDER/CovidE2EPipeDag.py', '--cfg-path', '/var/folders/vm/rn9v1g1j739_mq8j5pfl1yxm0000gn/T/tmpkun3cmj5']
[2025-01-03T21:44:47.734-0800] {standard_task_runner.py:105} INFO - Job 611: Subtask insert_staged_raw_data
[2025-01-03T21:44:47.854-0800] {task_command.py:467} INFO - Running <TaskInstance: CovidE2EPipeDag.insert_staged_raw_data scheduled__2025-01-01T00:34:00+00:00 [running]> on host Matthews-MacBook-Air.local
[2025-01-03T21:44:47.970-0800] {taskinstance.py:3132} INFO - Exporting env vars: AIRFLOW_CTX_DAG_OWNER='Matthew Horn' AIRFLOW_CTX_DAG_ID='CovidE2EPipeDag' AIRFLOW_CTX_TASK_ID='insert_staged_raw_data' AIRFLOW_CTX_EXECUTION_DATE='2025-01-01T00:34:00+00:00' AIRFLOW_CTX_TRY_NUMBER='2' AIRFLOW_CTX_DAG_RUN_ID='scheduled__2025-01-01T00:34:00+00:00'
[2025-01-03T21:44:47.973-0800] {logging_mixin.py:190} INFO - Task instance is in running state
[2025-01-03T21:44:47.974-0800] {logging_mixin.py:190} INFO -  Previous state of the Task instance: queued
[2025-01-03T21:44:47.975-0800] {logging_mixin.py:190} INFO - Current task name:insert_staged_raw_data state:running start_date:2025-01-04 05:44:47.671658+00:00
[2025-01-03T21:44:47.976-0800] {logging_mixin.py:190} INFO - Dag name:CovidE2EPipeDag and current dag run status:running
[2025-01-03T21:44:47.976-0800] {taskinstance.py:731} INFO - ::endgroup::
[2025-01-03T21:44:47.978-0800] {subprocess.py:78} INFO - Tmp dir root location: /var/folders/vm/rn9v1g1j739_mq8j5pfl1yxm0000gn/T
[2025-01-03T21:44:47.979-0800] {subprocess.py:88} INFO - Running command: ['/bin/bash', '-c', 'snow stage execute @raw_data_stage/load_staged_data_2025-01-03.sql']
[2025-01-03T21:44:47.993-0800] {subprocess.py:99} INFO - Output:
[2025-01-03T21:44:54.852-0800] {subprocess.py:106} INFO - 
[2025-01-03T21:44:54.854-0800] {subprocess.py:106} INFO - An unexpected exception occurred. Use --debug option to see the traceback. Exception message:
[2025-01-03T21:44:54.856-0800] {subprocess.py:106} INFO - 
[2025-01-03T21:44:54.857-0800] {subprocess.py:106} INFO - 090106 (22000): 01b97ad8-0004-5b31-0003-5bfb0001f80a: Cannot perform STAGE LS. This session does not have a current schema. Call 'USE SCHEMA', or use a qualified name.
[2025-01-03T21:44:55.457-0800] {subprocess.py:110} INFO - Command exited with return code 1
[2025-01-03T21:44:55.473-0800] {taskinstance.py:3311} ERROR - Task failed with exception
Traceback (most recent call last):
  File "/opt/anaconda3/envs/airflow_env/lib/python3.9/site-packages/airflow/models/taskinstance.py", line 767, in _execute_task
    result = _execute_callable(context=context, **execute_callable_kwargs)
  File "/opt/anaconda3/envs/airflow_env/lib/python3.9/site-packages/airflow/models/taskinstance.py", line 733, in _execute_callable
    return ExecutionCallableRunner(
  File "/opt/anaconda3/envs/airflow_env/lib/python3.9/site-packages/airflow/utils/operator_helpers.py", line 252, in run
    return self.func(*args, **kwargs)
  File "/opt/anaconda3/envs/airflow_env/lib/python3.9/site-packages/airflow/models/baseoperator.py", line 422, in wrapper
    return func(self, *args, **kwargs)
  File "/opt/anaconda3/envs/airflow_env/lib/python3.9/site-packages/airflow/operators/bash.py", line 276, in execute
    raise AirflowException(
airflow.exceptions.AirflowException: Bash command failed. The command returned a non-zero exit code 1.
[2025-01-03T21:44:55.483-0800] {logging_mixin.py:190} INFO - Task instance in failure state
[2025-01-03T21:44:55.484-0800] {logging_mixin.py:190} INFO - Task start:2025-01-04 05:44:47.671658+00:00 end:2025-01-04 05:44:55.482112+00:00 duration:7.810454
[2025-01-03T21:44:55.487-0800] {logging_mixin.py:190} INFO - Task:<Task(BashOperator): insert_staged_raw_data> dag:<DAG: CovidE2EPipeDag> dagrun:<DagRun CovidE2EPipeDag @ 2025-01-01 00:34:00+00:00: scheduled__2025-01-01T00:34:00+00:00, state:running, queued_at: 2025-01-04 05:36:47.440912+00:00. externally triggered: False>
[2025-01-03T21:44:55.489-0800] {logging_mixin.py:190} INFO - Failure caused by Bash command failed. The command returned a non-zero exit code 1.
[2025-01-03T21:44:55.491-0800] {taskinstance.py:1225} INFO - Marking task as FAILED. dag_id=CovidE2EPipeDag, task_id=insert_staged_raw_data, run_id=scheduled__2025-01-01T00:34:00+00:00, execution_date=20250101T003400, start_date=20250104T054447, end_date=20250104T054455
[2025-01-03T21:44:55.513-0800] {taskinstance.py:340} INFO - ::group::Post task execution logs
[2025-01-03T21:44:55.515-0800] {standard_task_runner.py:124} ERROR - Failed to execute job 611 for task insert_staged_raw_data (Bash command failed. The command returned a non-zero exit code 1.; 70917)
Traceback (most recent call last):
  File "/opt/anaconda3/envs/airflow_env/lib/python3.9/site-packages/airflow/task/task_runner/standard_task_runner.py", line 117, in _start_by_fork
    ret = args.func(args, dag=self.dag)
  File "/opt/anaconda3/envs/airflow_env/lib/python3.9/site-packages/airflow/cli/cli_config.py", line 49, in command
    return func(*args, **kwargs)
  File "/opt/anaconda3/envs/airflow_env/lib/python3.9/site-packages/airflow/utils/cli.py", line 116, in wrapper
    return f(*args, **kwargs)
  File "/opt/anaconda3/envs/airflow_env/lib/python3.9/site-packages/airflow/cli/commands/task_command.py", line 483, in task_run
    task_return_code = _run_task_by_selected_method(args, _dag, ti)
  File "/opt/anaconda3/envs/airflow_env/lib/python3.9/site-packages/airflow/cli/commands/task_command.py", line 256, in _run_task_by_selected_method
    return _run_raw_task(args, ti)
  File "/opt/anaconda3/envs/airflow_env/lib/python3.9/site-packages/airflow/cli/commands/task_command.py", line 341, in _run_raw_task
    return ti._run_raw_task(
  File "/opt/anaconda3/envs/airflow_env/lib/python3.9/site-packages/airflow/utils/session.py", line 97, in wrapper
    return func(*args, session=session, **kwargs)
  File "/opt/anaconda3/envs/airflow_env/lib/python3.9/site-packages/airflow/models/taskinstance.py", line 3005, in _run_raw_task
    return _run_raw_task(
  File "/opt/anaconda3/envs/airflow_env/lib/python3.9/site-packages/airflow/models/taskinstance.py", line 273, in _run_raw_task
    TaskInstance._execute_task_with_callbacks(
  File "/opt/anaconda3/envs/airflow_env/lib/python3.9/site-packages/airflow/models/taskinstance.py", line 3159, in _execute_task_with_callbacks
    result = self._execute_task(context, task_orig)
  File "/opt/anaconda3/envs/airflow_env/lib/python3.9/site-packages/airflow/models/taskinstance.py", line 3183, in _execute_task
    return _execute_task(self, context, task_orig)
  File "/opt/anaconda3/envs/airflow_env/lib/python3.9/site-packages/airflow/models/taskinstance.py", line 767, in _execute_task
    result = _execute_callable(context=context, **execute_callable_kwargs)
  File "/opt/anaconda3/envs/airflow_env/lib/python3.9/site-packages/airflow/models/taskinstance.py", line 733, in _execute_callable
    return ExecutionCallableRunner(
  File "/opt/anaconda3/envs/airflow_env/lib/python3.9/site-packages/airflow/utils/operator_helpers.py", line 252, in run
    return self.func(*args, **kwargs)
  File "/opt/anaconda3/envs/airflow_env/lib/python3.9/site-packages/airflow/models/baseoperator.py", line 422, in wrapper
    return func(self, *args, **kwargs)
  File "/opt/anaconda3/envs/airflow_env/lib/python3.9/site-packages/airflow/operators/bash.py", line 276, in execute
    raise AirflowException(
airflow.exceptions.AirflowException: Bash command failed. The command returned a non-zero exit code 1.
[2025-01-03T21:44:55.558-0800] {local_task_job_runner.py:266} INFO - Task exited with return code 1
[2025-01-03T21:44:55.592-0800] {taskinstance.py:3895} INFO - 0 downstream tasks scheduled from follow-on schedule check
[2025-01-03T21:44:55.594-0800] {local_task_job_runner.py:245} INFO - ::endgroup::
